<?xml version="1.0"?>
<robot name="suspension_right" xmlns:xacro="http://www.ros.org/wiki/xacro">
    <xacro:macro name="suspension_rigth" params="">
    
        <joint name="suspension_rigth_tree_root_joint" type="continuous">
            <origin xyz="${rocker_right_offset}" rpy="0.0 0.0 0.0"/>
            <parent link="chassis_link"/>
            <child link="rocker_right_link"/>
            <axis xyz="1.0 0.0 0.0"/>
        </joint>
        <link name="rocker_right_link">
            <inertial>
                <origin xyz="${rocker_left_mass_center_xyz}" rpy="0.0 0.0 0.0"/>
                <mass value="${rocker_left_mass}"/>
                <inertia    ixx="0.0077"    ixy="-0.0005"   ixz="0.0022" 
                                            iyy="0.0098"    iyz="-0.0003"
                                                            izz="0.0015"/>
            </inertial>
            <visual>
                <origin xyz="0.0 0.0 0.0" rpy="0.0 0.0 0.0"/>
                <geometry>
                    <mesh filename="package://rover_description/meshes/MirrorRocker.STL" scale="${SCALE_XYZ}"/>
                </geometry>
                <material name="white">
                </material>
            </visual>
            <collision>
                <origin xyz="0.0 0.0 0.0" rpy="0.0 0.0 ${-PI/2}"/>
                <geometry>
                    <mesh filename="package://rover_description/meshes/MirrorRocker.STL" scale="${SCALE_XYZ}"/>
                </geometry>
            </collision>
        </link>
        <!--
        <joint name="rocker_bogie_right" type="continuous">
            <origin xyz="${bogie_pivot_left_offset}" rpy="0.0 0.0 0.0"/>
            <parent link="rocker_left_link"/>
            <child link="bogie_pivot_right_link"/>
            <axis xyz="1.0 0.0 0.0"/>
        </joint>
        <link name="bogie_pivot_right_link">
            <inertial>
                <origin xyz="${bogie_pivot_left_mass_center_xyz}" rpy="0.0 0.0 0.0"/>
                <mass value="${bogie_pivot_left_mass}"/>
                <inertia    ixx="0.0684"    ixy="0.0038"    ixz="0.0" 
                                            iyy="0.0572"    iyz="-0.0028" 
                                                            izz="0.0425"/>
            </inertial>
            <visual>
                <origin xyz="0.0 0.0 0.0" rpy="0.0 0.0 0.0"/>
                <geometry>
                    <mesh filename="package://rover_description/meshes/Bogie_pivot.STL" scale="${SCALE_XYZ}"/>
                </geometry>
                <material name="white">
                </material>
            </visual>
            <collision>
                <origin xyz="0.0 0.0 0.0" rpy="0.0 0.0 0.0"/>
                <geometry>
                    <mesh filename="package://rover_description/meshes/Bogie_pivot.STL" scale="${SCALE_XYZ}"/>
                </geometry>
            </collision>
        </link>
        -->

    </xacro:macro>
</robot>